Workbook
Name UPDATE: 'Data Sheet'!$E$1

Sheet DCF>

Sheet DCF
B2: ='Data Sheet'!B1 -> ITC LTD
B3: DCF
B5: Calculation of PV of FCFF
B7: Particulars | D7: ='Historicals FS'!L3 -> 46112 | E7: =D7+365 -> 46477 | F7: =E7+365 -> 46842 | G7: =F7+365 -> 47207 | H7: =G7+365 -> 47572 | I7: =H7+365 -> 47937
B8: EBIT | D8: ='Historicals FS'!L23 -> 25595.47 | E8: =D8*(1+E$9) -> 28546.858 | F8: =E8*(1+F$9) -> 31194.058 | G8: =F8*(1+G$9) -> 33382.461 | H8: =G8*(1+H$9) -> 34970.707 | I8: =H8*(1+I$9) -> 35844.975
B9: Faded Growth Rate | E9: =$D$21-(($D$21-$D$22)/5) -> 0.115309 | F9: =E9-(($D$21-$D$22)/5) -> 0.092731748 | G9: =F9-(($D$21-$D$22)/5) -> 0.070154498 | H9: =G9-(($D$21-$D$22)/5) -> 0.047577249 | I9: =H9-(($D$21-$D$22)/5) -> 0.025
B10: Tax Rate | D10: ='Master Input Center'!$C$4 -> 0.2517 | E10: ='Master Input Center'!$C$4 -> 0.2517 | F10: ='Master Input Center'!$C$4 -> 0.2517 | G10: ='Master Input Center'!$C$4 -> 0.2517 | H10: ='Master Input Center'!$C$4 -> 0.2517 | I10: ='Master Input Center'!$C$4 -> 0.2517
B11: NOPAT | D11: =D8*(1-D10) -> 19153.09 | E11: =E8*(1-E10) -> 21361.614 | F11: =F8*(1-F10) -> 23342.514 | G11: =G8*(1-G10) -> 24980.096 | H11: =H8*(1-H10) -> 26168.58 | I11: =I8*(1-I10) -> 26822.795
B12: Reinvestment rate | D12: ='Master Input Center'!C30 -> 0.1818709 | E12: =D12+(($I$12-$D$12)/5) -> 0.16549672 | F12: =E12+(($I$12-$D$12)/4) -> 0.14502899 | G12: =F12+(($I$12-$D$12)/4) -> 0.12456127 | H12: =G12+(($I$12-$D$12)/4) -> 0.10409354 | I12: ='Master Input Center'!C35 -> 0.1
B13: Free Cash Flow to firm | D13: =D11*(1-D12) -> 15669.7 | E13: =E11*(1-E12) -> 17826.337 | F13: =F11*(1-F12) -> 19957.172 | G13: =G11*(1-G12) -> 21868.543 | H13: =H11*(1-H12) -> 23444.6 | I13: =I11*(1-I12) -> 24140.515
B14: Mid Year convention | D14: 0 | E14: ='Master Input Center'!C36 -> 0.5 | F14: =YEARFRAC($E$7,F7,0)+$E$14 -> 1.5 | G14: =YEARFRAC($E$7,G7,0)+$E$14 -> 2.5 | H14: =YEARFRAC($E$7,H7,0)+$E$14 -> 3.5 | I14: =YEARFRAC($E$7,I7,0)+$E$14 -> 4.5
B15: Discounting Factor | D15: 0 | E15: =1/(1+$D$23)^E14 -> 0.95144421 | F15: =1/(1+$D$23)^F14 -> 0.86129115 | G15: =1/(1+$D$23)^G14 -> 0.77968044 | H15: =1/(1+$D$23)^H14 -> 0.70580267 | I15: =1/(1+$D$23)^I14 -> 0.63892511
B17: Pv of FCFF | E17: =E13*E15 -> 16960.765 | F17: =F13*F15 -> 17188.936 | G17: =G13*G15 -> 17050.476 | H17: =H13*H15 -> 16547.261 | I17: =I13*I15 -> 15423.981
F19: Calculation of Equity Value
B21: Growth Rate | D21: ='Master Input Center'!C31 -> 0.13788625 | F21: PV of FCFF | I21: =SUM(E13:I13) -> 107237.17
B22: Terminal Growth Rate | D22: ='Master Input Center'!C33 -> 0.025 | F22: Pv of Terminal Value | I22: =$D$31/(1+$D$23)^5 -> 133913.06
B23: WACC | D23: ='Master Input Center'!C32 -> 0.10467199 | F23: Value of Opening Asset | I23: =SUM(I21:I22) -> 241150.23
B25: Calculation of Terminal Value | F25: Add : Cash | I25: ='Raw Fs'!N45 -> 3009
F26: Add : Investments | I26: ='Raw Fs'!N35 -> 38128
B27: Normalized Base FCFF | D27: =I17*(1+$D$21) -> 17550.736 | F27: Less : Debt | I27: =SUM('Raw Fs'!N8:N9) -> 2186
B28: =B23 -> WACC | D28: =D23 -> 0.10467199 | F28: Value of Equity | I28: =I23+I25+I26-I27 -> 280101.23
B29: =B22 -> Terminal Growth Rate | D29: =D22 -> 0.025 | F29: No.of Shares | I29: ='Data Sheet'!K93 -> 1252.95
B31: Terminal Value | D31: =D27/(D28-D29) -> 220287.4 | F31: Equity value Per Share | I31: =I28/I29 -> 223.5534
B32: Conclusion: At a current market price of ₹268.00, ITC Ltd trades at a 1.20x premium to its intrinsic fair value of ₹223.60. The valuation incorporates a fading growth rate (13.79% tapering linearly to a 2.50% terminal growth rate), a stable cost of capital (10.47%) anchored to long-term target capital weights, and adds back ₹38,128 Cr of standalone investments (current and non-current, per Notes 4 and 9) as non-operating assets not captured within EBIT.
F33: Share Price | I33: 268
F34: =IF(I33>I31,"Premium","Discount") -> Premium | I34: =IF(I31>I33,1-(I33/I31),IF(I31<I33,(I33/I31)-1,0)) -> 0.19881873
B36: Sensitivity Table
C37: =I31 -> 223.5534 | D37: =E37-0.005 -> 0.094671993 | E37: =F37-0.005 -> 0.099671993 | F37: =$D$23 -> 0.10467199 | G37: =F37+0.005 -> 0.10967199 | H37: =G37+0.005 -> 0.11467199
C38: =C39-0.005 -> 0.02 | D38: 230.70991 | E38: 223.5534 | F38: 217.24209 | G38: 211.6346 | H38: 206.61942
B39: =F31 -> Equity value Per Share | C39: =$D$22 -> 0.025 | D39: 238.8936 | E39: 230.70991 | F39: 223.5534 | G39: 217.24209 | H39: 211.6346
C40: =C39+0.005 -> 0.03 | D40: 248.34269 | E40: 238.8936 | F40: 230.70991 | G40: 223.5534 | H40: 217.24209
C41: =C40+0.005 -> 0.035 | D41: 259.3753 | E41: 248.34269 | F41: 238.8936 | G41: 230.70991 | H41: 223.5534
C42: =C41+0.005 -> 0.04 | D42: 272.42587 | E42: 259.3753 | F42: 248.34269 | G42: 238.8936 | H42: 230.70991
C44: =I28 -> 280101.23 | D44: =E44-0.005 -> 0.094671993 | E44: =F44-0.005 -> 0.099671993 | F44: =$D$23 -> 0.10467199 | G44: =F44+0.005 -> 0.10967199 | H44: =G44+0.005 -> 0.11467199
C45: =C46-0.005 -> 0.02 | D45: 289067.98 | E45: 280101.23 | F45: 272193.48 | G45: 265167.57 | H45: 258883.8
B46: =F28 -> Value of Equity | C46: =$D$22 -> 0.025 | D46: 299321.73 | E46: 289067.98 | F46: 280101.23 | G46: 272193.48 | H46: 265167.57
C47: =C46+0.005 -> 0.03 | D47: 311160.98 | E47: 299321.73 | F47: 289067.98 | G47: 280101.23 | H47: 272193.48
C48: =C47+0.005 -> 0.035 | D48: 324984.28 | E48: 311160.98 | F48: 299321.73 | G48: 289067.98 | H48: 280101.23
C49: =C48+0.005 -> 0.04 | D49: 341335.99 | E49: 324984.28 | F49: 311160.98 | G49: 299321.73 | H49: 289067.98
B51: Notes
...

Sheet WACC
B2: Weighted Average Cost of Capital
B4: Cost of Debt | G4: Cost of Equity
B6: Pre Tax Cost of Debt | E6: ='Master Input Center'!C21+'Master Input Center'!C22 -> 0.0727 | G6: Risk Free Rate | J6: ='Master Input Center'!C21 -> 0.0677
B7: Tax Rate | E7: ='Master Input Center'!C4 -> 0.2517 | G7: ERP | J7: ='Master Input Center'!C23 -> 0.0416
G8: Levered Beta | J8: ='Master Input Center'!C25 -> 0.89703267
B10: Post Tax Cost of Debt | E10: =E6*(1-E7) -> 0.05440141 | G10: Cost of Equity | J10: =J6+(J7*J8) -> 0.10501656
B12: Capital Structure | G12: Levered Beta (Peer Comps)
D13: Current | E13: Target
B14: Debt | C14: ='Comps Beta Calculation'!F20 -> 2399.06 | D14: =C14/$C$16 -> 0.0068075697 | E14: =D14 -> 0.0068075697 | G14: Comps Median Unlevered Beta | J14: ='Comps Beta Calculation'!K28 -> 0.94891811
B15: Equity | C15: ='Comps Beta Calculation'!E20 -> 350011.58 | D15: =C15/$C$16 -> 0.99319243 | E15: =D15 -> 0.99319243 | G15: Tax Rate | J15: ='Master Input Center'!C4 -> 0.2517
B16: Total | C16: =SUM(C14:C15) -> 352410.64 | D16: =C16/$C$16 -> 1 | E16: =D16 -> 1 | G16: Target Debt to Equity | J16: =E18 -> 0.0068542303
B18: Debt to Equity | D18: =D14/D15 -> 0.0068542303 | E18: =E14/E15 -> 0.0068542303 | G18: Levered Beta | J18: =J14*(1+(1-J15)*J16) -> 0.95378513
B19: Note on Capital Structure: WACC weights are hardcoded to management's long-term target capital structure (~99.3% Equity / 0.7% Debt). This framework is intentionally unlinked from the dynamic intrinsic value of equity to prevent circularity and to reflect the steady-state capitalized profile of the firm.
B21: Weighted Average Cost of Capital
B23: Cost of Equity | E23: =J10 -> 0.10501656
B24: Equity Weight | E24: =D15 -> 0.99319243
B25: Cost of Debt | E25: =E10 -> 0.05440141
B26: Debt Weight | E26: =D14 -> 0.0068075697
B28: WACC | E28: =(E23*E24)+(E25*E26) -> 0.10467199

Sheet Intrinsic Growth
B2: Calculation Of Intrinsic Growth
B3: Particulars | C3: ='Raw Fs'!I3 -> 44256 | D3: ='Raw Fs'!J3 -> 44621 | E3: ='Raw Fs'!K3 -> 44986 | F3: ='Raw Fs'!L3 -> 45352 | G3: ='Raw Fs'!M3 -> 45717 | H3: ='Raw Fs'!N3 -> 46082
B5: Calculation of ROIC
A7: # | B7: Current Assets
B8: ='Raw Fs'!B38 -> Inventories | C8: ='Raw Fs'!I38 -> 10397 | D8: ='Raw Fs'!J38 -> 10864 | E8: ='Raw Fs'!K38 -> 11771 | F8: ='Raw Fs'!L38 -> 14153 | G8: ='Raw Fs'!M38 -> 15638 | H8: ='Raw Fs'!N38 -> 18623
B9: ='Raw Fs'!B40 -> Trade receivables - | C9: =SUM('Raw Fs'!I41:I43) -> 2501 | D9: =SUM('Raw Fs'!J41:J43) -> 2462 | E9: =SUM('Raw Fs'!K41:K43) -> 2956 | F9: =SUM('Raw Fs'!L41:L43) -> 4026 | G9: =SUM('Raw Fs'!M41:M43) -> 4720 | H9: =SUM('Raw Fs'!N41:N43) -> 3923
B10: ='Raw Fs'!B46 -> Loans n Advances | C10: ='Raw Fs'!I46 -> 7 | D10: ='Raw Fs'!J46 -> 11 | E10: ='Raw Fs'!K46 -> 13 | F10: ='Raw Fs'!L46 -> 31 | G10: ='Raw Fs'!M46 -> 10 | H10: ='Raw Fs'!N46 -> 9
B11: ='Raw Fs'!B47 -> Other asset items | C11: ='Raw Fs'!I47 -> 4015 | D11: ='Raw Fs'!J47 -> 6906 | E11: ='Raw Fs'!K47 -> 7941 | F11: ='Raw Fs'!L47 -> 4531 | G11: ='Raw Fs'!M47 -> 5858 | H11: ='Raw Fs'!N47 -> 5901
B13: Current Assets | C13: =SUM(C8:C11) -> 16920 | D13: =SUM(D8:D11) -> 20243 | E13: =SUM(E8:E11) -> 22681 | F13: =SUM(F8:F11) -> 22741 | G13: =SUM(G8:G11) -> 26226 | H13: =SUM(H8:H11) -> 28456
A15: # | B15: Current Liabilities
B16: ='Raw Fs'!B13 -> Non controlling int | C16: ='Raw Fs'!I13 -> 347 | D16: ='Raw Fs'!J13 -> 366 | E16: ='Raw Fs'!K13 -> 384 | F16: ='Raw Fs'!L13 -> 383 | G16: ='Raw Fs'!M13 -> 368 | H16: ='Raw Fs'!N13 -> 366
B17: ='Raw Fs'!B14 -> Trade Payables | C17: ='Raw Fs'!I14 -> 4319 | D17: ='Raw Fs'!J14 -> 4417 | E17: ='Raw Fs'!K14 -> 4659 | F17: ='Raw Fs'!L14 -> 4798 | G17: ='Raw Fs'!M14 -> 4807 | H17: ='Raw Fs'!N14 -> 5640
B18: ='Raw Fs'!B15 -> Advance from Customers | C18: ='Raw Fs'!I15 -> 811 | D18: ='Raw Fs'!J15 -> 1278 | E18: ='Raw Fs'!K15 -> 1295 | F18: ='Raw Fs'!L15 -> 886 | G18: ='Raw Fs'!M15 -> 1264 | H18: ='Raw Fs'!N15 -> 1342
B19: ='Raw Fs'!B16 -> Other liability items | C19: ='Raw Fs'!I16 -> 7666 | D19: ='Raw Fs'!J16 -> 8429 | E19: ='Raw Fs'!K16 -> 10032 | F19: ='Raw Fs'!L16 -> 10877 | G19: ='Raw Fs'!M16 -> 11249 | H19: ='Raw Fs'!N16 -> 11384
B21: Current Liabilities | C21: =SUM(C16:C19) -> 13143 | D21: =SUM(D16:D19) -> 14490 | E21: =SUM(E16:E19) -> 16370 | F21: =SUM(F16:F19) -> 16944 | G21: =SUM(G16:G19) -> 17688 | H21: =SUM(H16:H19) -> 18732
B23: Net Non Cash Working Capital | C23: =C13-C21 -> 3777 | D23: =D13-D21 -> 5753 | E23: =E13-E21 -> 6311 | F23: =F13-F21 -> 5797 | G23: =G13-G21 -> 8538 | H23: =H13-H21 -> 9724
A25: # | B25: Fixed Assets
B26: ='Raw Fs'!B21 -> Land | C26: ='Raw Fs'!I21 -> 2889 | D26: ='Raw Fs'!J21 -> 2829 | E26: ='Raw Fs'!K21 -> 2830 | F26: ='Raw Fs'!L21 -> 2865 | G26: ='Raw Fs'!M21 -> 1588 | H26: ='Raw Fs'!N21 -> 1633
B27: ='Raw Fs'!B22 -> Building | C27: ='Raw Fs'!I22 -> 8387 | D27: ='Raw Fs'!J22 -> 9100 | E27: ='Raw Fs'!K22 -> 9789 | F27: ='Raw Fs'!L22 -> 10944 | G27: ='Raw Fs'!M22 -> 7550 | H27: ='Raw Fs'!N22 -> 7791
B28: ='Raw Fs'!B23 -> Plant Machinery | C28: ='Raw Fs'!I23 -> 15307 | D28: ='Raw Fs'!J23 -> 16912 | E28: ='Raw Fs'!K23 -> 18480 | F28: ='Raw Fs'!L23 -> 20718 | G28: ='Raw Fs'!M23 -> 19423 | H28: ='Raw Fs'!N23 -> 20424
B29: ='Raw Fs'!B24 -> Equipment | C29: ='Raw Fs'!I24 -> 41 | D29: ='Raw Fs'!J24 -> 44 | E29: ='Raw Fs'!K24 -> 44 | F29: ='Raw Fs'!L24 -> 53 | G29: ='Raw Fs'!M24 -> 63 | H29: ='Raw Fs'!N24 -> 75
B30: ='Raw Fs'!B25 -> Furniture n fittings | C30: ='Raw Fs'!I25 -> 833 | D30: ='Raw Fs'!J25 -> 907 | E30: ='Raw Fs'!K25 -> 1000 | F30: ='Raw Fs'!L25 -> 1068 | G30: ='Raw Fs'!M25 -> 282 | H30: ='Raw Fs'!N25 -> 304
B31: ='Raw Fs'!B26 -> Railway sidings | C31: ='Raw Fs'!I26 -> 2 | D31: ='Raw Fs'!J26 -> 2 | E31: ='Raw Fs'!K26 -> 2 | F31: ='Raw Fs'!L26 -> 2 | G31: ='Raw Fs'!M26 -> 2 | H31: ='Raw Fs'!N26 -> 2
B32: ='Raw Fs'!B27 -> Vehicles | C32: ='Raw Fs'!I27 -> 180 | D32: ='Raw Fs'!J27 -> 179 | E32: ='Raw Fs'!K27 -> 189 | F32: ='Raw Fs'!L27 -> 192 | G32: ='Raw Fs'!M27 -> 141 | H32: ='Raw Fs'!N27 -> 155
B33: ='Raw Fs'!B28 -> Intangible Assets | C33: ='Raw Fs'!I28 -> 2734 | D33: ='Raw Fs'!J28 -> 2744 | E33: ='Raw Fs'!K28 -> 3490 | F33: ='Raw Fs'!L28 -> 3505 | G33: ='Raw Fs'!M28 -> 3622 | H33: ='Raw Fs'!N28 -> 4248
B34: ='Raw Fs'!B29 -> Other fixed assets | C34: ='Raw Fs'!I29 -> 716 | D34: ='Raw Fs'!J29 -> 719 | E34: ='Raw Fs'!K29 -> 786 | F34: ='Raw Fs'!L29 -> 841 | G34: ='Raw Fs'!M29 -> 967 | H34: ='Raw Fs'!N29 -> 1041
B35: ='Raw Fs'!B30 -> Gross Block | C35: =SUM(C26:C34) -> 31089 | D35: =SUM(D26:D34) -> 33436 | E35: =SUM(E26:E34) -> 36610 | F35: =SUM(F26:F34) -> 40188 | G35: =SUM(G26:G34) -> 33638 | H35: =SUM(H26:H34) -> 35673
B36: ='Raw Fs'!B31 -> Accumulated Depreciation | C36: =-'Raw Fs'!I31 -> -7790 | D36: =-'Raw Fs'!J31 -> -9204 | E36: =-'Raw Fs'!K31 -> -10757 | F36: =-'Raw Fs'!L31 -> -12368 | G36: =-'Raw Fs'!M31 -> -11683 | H36: =-'Raw Fs'!N31 -> -13230
B38: ='Raw Fs'!B32 -> Net Block | C38: =C35+C36 -> 23299 | D38: =D35+D36 -> 24232 | E38: =E35+E36 -> 25853 | F38: =F35+F36 -> 27820 | G38: =G35+G36 -> 21955 | H38: =H35+H36 -> 22443
A40: # | B40: Invested Capital | C40: =C23+C38 -> 27076 | D40: =D23+D38 -> 29985 | E40: =E23+E38 -> 32164 | F40: =F23+F38 -> 33617 | G40: =G23+G38 -> 30493 | H40: =H23+H38 -> 32167
B41: ='Historicals FS'!B23 -> EBIT | C41: ='Historicals FS'!G23 -> 15419.19 | D41: ='Historicals FS'!H23 -> 18890.74 | E41: ='Historicals FS'!I23 -> 23895.25 | F41: ='Historicals FS'!J23 -> 23669.48 | G41: ='Historicals FS'!K23 -> 24185.26 | H41: ='Historicals FS'!L23 -> 25595.47
B43: ROIC | C43: =C41/C40 -> 0.56947814 | D43: =D41/D40 -> 0.63000634 | E43: =E41/E40 -> 0.7429191 | F43: =F41/F40 -> 0.70409257 | G43: =G41/G40 -> 0.79314138 | H43: =H41/H40 -> 0.79570585
F45: Five Year Average | H45: =AVERAGE(C43:H43) -> 0.70589056
F46: Five Year Median | H46: =MEDIAN(C43:H43) -> 0.72350584
B50: Calculation of Reinvestment Rate
B52: Net Capex | D52: =-SUM('Cash Flows'!J13:J14) -> 2009 | E52: =-SUM('Cash Flows'!K13:K14) -> 2694 | F52: =-SUM('Cash Flows'!L13:L14) -> 3456 | G52: =-SUM('Cash Flows'!M13:M14) -> 2104 | H52: =-SUM('Cash Flows'!N13:N14) -> 2133
B53: Change in Working Capital | D53: =D23-C23 -> 1976 | E53: =E23-D23 -> 558 | F53: =F23-E23 -> -514 | G53: =G23-F23 -> 2741 | H53: =H23-G23 -> 1186
B55: Reinvestment Amount | D55: =D52+D53 -> 3985 | E55: =E52+E53 -> 3252 | F55: =F52+F53 -> 2942 | G55: =G52+G53 -> 4845 | H55: =H52+H53 -> 3319
B57: EBIT | D57: =D41 -> 18890.74 | E57: =E41 -> 23895.25 | F57: =F41 -> 23669.48 | G57: =G41 -> 24185.26 | H57: =H41 -> 25595.47
B58: Tax Rate | D58: ='Master Input Center'!$C$4 -> 0.2517 | E58: ='Master Input Center'!$C$4 -> 0.2517 | F58: ='Master Input Center'!$C$4 -> 0.2517 | G58: ='Master Input Center'!$C$4 -> 0.2517 | H58: ='Master Input Center'!$C$4 -> 0.2517
...

Sheet Comps Beta Calculation
B2: Beta Calculation
B4: Comps
B7: Beta Drifting (peer comps)
C8: Raw | D8: Raw | E8: Raw Beta | F8: Market | G8: Market Beta | H8: Adjusted
B9: Company Name | C9: Beta1 | D9: Beta2 | E9: Weight | F9: Beta | G9: Weight | H9: Beta
B10: ='Daily Adjusted closings'!I3 -> ITC LTD | C10: =SLOPE('Daily Adjusted closings'!J6:J64,'Daily Adjusted closings'!$G$6:$G$64) -> 0.84554901 | D10: =_xlfn.COVARIANCE.S('Daily Adjusted closings'!J6:J64,'Daily Adjusted closings'!$G$6:$G$64)/_xlfn.VAR.S('Daily Adjusted closings'!$G$6:$G$64) -> 0.84554901 | E10: ='Master Input Center'!$C$16 -> 0.66666667 | F10: ='Master Input Center'!$C$15 -> 1 | G10: ='Master Input Center'!$C$17 -> 0.33333333 | H10: =(C10*E10)+(F10*G10) -> 0.89703267
B11: ='Daily Adjusted closings'!L3 -> Hindustan Unilever Ltd | C11: =SLOPE('Daily Adjusted closings'!M6:M64,'Daily Adjusted closings'!$G$6:$G$64) -> 0.8846964 | D11: =_xlfn.COVARIANCE.S('Daily Adjusted closings'!M6:M64,'Daily Adjusted closings'!$G$6:$G$64)/_xlfn.VAR.S('Daily Adjusted closings'!$G$6:$G$64) -> 0.8846964 | E11: ='Master Input Center'!$C$16 -> 0.66666667 | F11: ='Master Input Center'!$C$15 -> 1 | G11: ='Master Input Center'!$C$17 -> 0.33333333 | H11: =(C11*E11)+(F11*G11) -> 0.92313093
B12: ='Daily Adjusted closings'!O3 -> Nestle India Ltd | C12: =SLOPE('Daily Adjusted closings'!P6:P64,'Daily Adjusted closings'!$G$6:$G$64) -> 1.0413293 | D12: =_xlfn.COVARIANCE.S('Daily Adjusted closings'!P6:P64,'Daily Adjusted closings'!$G$6:$G$64)/_xlfn.VAR.S('Daily Adjusted closings'!$G$6:$G$64) -> 1.0413293 | E12: ='Master Input Center'!$C$16 -> 0.66666667 | F12: ='Master Input Center'!$C$15 -> 1 | G12: ='Master Input Center'!$C$17 -> 0.33333333 | H12: =(C12*E12)+(F12*G12) -> 1.0275529
B13: ='Daily Adjusted closings'!R3 -> Britannia Industries Ltd | C13: =SLOPE('Daily Adjusted closings'!S6:S64,'Daily Adjusted closings'!$G$6:$G$64) -> 0.97746311 | D13: =_xlfn.COVARIANCE.S('Daily Adjusted closings'!S6:S64,'Daily Adjusted closings'!$G$6:$G$64)/_xlfn.VAR.S('Daily Adjusted closings'!$G$6:$G$64) -> 0.97746311 | E13: ='Master Input Center'!$C$16 -> 0.66666667 | F13: ='Master Input Center'!$C$15 -> 1 | G13: ='Master Input Center'!$C$17 -> 0.33333333 | H13: =(C13*E13)+(F13*G13) -> 0.9849754
B14: ='Daily Adjusted closings'!U3 -> Godrej Consumer Products Limited | C14: =SLOPE('Daily Adjusted closings'!V6:V64,'Daily Adjusted closings'!$G$6:$G$64) -> 1.0238073 | D14: =_xlfn.COVARIANCE.S('Daily Adjusted closings'!V6:V64,'Daily Adjusted closings'!$G$6:$G$64)/_xlfn.VAR.S('Daily Adjusted closings'!$G$6:$G$64) -> 1.0238073 | E14: ='Master Input Center'!$C$16 -> 0.66666667 | F14: ='Master Input Center'!$C$15 -> 1 | G14: ='Master Input Center'!$C$17 -> 0.33333333 | H14: =(C14*E14)+(F14*G14) -> 1.0158715
B15: ='Daily Adjusted closings'!X3 -> Dabur India Ltd | C15: =SLOPE('Daily Adjusted closings'!Y6:Y64,'Daily Adjusted closings'!$G$6:$G$64) -> 0.86542745 | D15: =_xlfn.COVARIANCE.S('Daily Adjusted closings'!Y6:Y64,'Daily Adjusted closings'!$G$6:$G$64)/_xlfn.VAR.S('Daily Adjusted closings'!$G$6:$G$64) -> 0.86542745 | E15: ='Master Input Center'!$C$16 -> 0.66666667 | F15: ='Master Input Center'!$C$15 -> 1 | G15: ='Master Input Center'!$C$17 -> 0.33333333 | H15: =(C15*E15)+(F15*G15) -> 0.91028497
B17: Peer comps Data Table
H18: Debt/ | I18: Debt/ | J18: Levered | K18: Unlevered
B19: =B9 -> Company Name | C19: Ticker | D19: Country | E19: Equity | F19: Debt | G19: Tax | H19: Equity | I19: Capital | J19: Beta | K19: Beta
B20: =B10 -> ITC LTD | C20: ='Daily Adjusted closings'!I4 -> ITC | D20: ='Master Input Center'!$C$14 -> India | E20: ='Comps Data'!G3 -> 350011.58 | F20: ='Comps Data'!H3 -> 2399.06 | G20: ='Master Input Center'!C4 -> 0.2517 | H20: =F20/E20 -> 0.0068542303 | I20: =F20/SUM(E20:F20) -> 0.0068075697 | J20: =H10 -> 0.89703267 | K20: =J20/(1+(1-G20)*H20) -> 0.89245525
B21: =B11 -> Hindustan Unilever Ltd | C21: ='Daily Adjusted closings'!L4 -> HINDUNILVR | D21: ='Master Input Center'!$C$14 -> India | E21: ='Comps Data'!G5 -> 493040.06 | F21: ='Comps Data'!H5 -> 1478 | G21: ='Comps Data'!V5 -> 0.22495907 | H21: =F21/E21 -> 0.002997728 | I21: =F21/SUM(E21:F21) -> 0.0029887685 | J21: =H11 -> 0.92313093 | K21: =J21/(1+(1-G21)*H21) -> 0.92099114
B22: =B12 -> Nestle India Ltd | C22: ='Daily Adjusted closings'!O4 -> NESTLEIND | D22: ='Master Input Center'!$C$14 -> India | E22: ='Comps Data'!G6 -> 274493.51 | F22: ='Comps Data'!H6 -> 444.16 | G22: ='Comps Data'!V6 -> 0.2374757 | H22: =F22/E22 -> 0.0016181075 | I22: =F22/SUM(E22:F22) -> 0.0016154935 | J22: =H12 -> 1.0275529 | K22: =J22/(1+(1-G22)*H22) -> 1.0262866
B23: =B13 -> Britannia Industries Ltd | C23: ='Daily Adjusted closings'!R4 -> BRITANNIA | D23: ='Master Input Center'!$C$14 -> India | E23: ='Comps Data'!G8 -> 127929.94 | F23: ='Comps Data'!H8 -> 1380.28 | G23: ='Comps Data'!V8 -> 0.22858628 | H23: =F23/E23 -> 0.010789343 | I23: =F23/SUM(E23:F23) -> 0.010674175 | J23: =H13 -> 0.9849754 | K23: =J23/(1+(1-G23)*H23) -> 0.97684508
B24: =B14 -> Godrej Consumer Products Limited | C24: ='Daily Adjusted closings'!U4 -> GODREJCP.NS | D24: ='Master Input Center'!$C$14 -> India | E24: ='Comps Data'!G10 -> 108234.44 | F24: ='Comps Data'!H10 -> 4415.81 | G24: ='Comps Data'!V10 -> 0.25809776 | H24: =F24/E24 -> 0.040798566 | I24: =F24/SUM(E24:F24) -> 0.039199291 | J24: =H14 -> 1.0158715 | K24: =J24/(1+(1-G24)*H24) -> 0.98602596
B25: =B15 -> Dabur India Ltd | C25: ='Daily Adjusted closings'!X4 -> DABUR | D25: ='Master Input Center'!$C$14 -> India | E25: ='Comps Data'!G13 -> 76184.43 | F25: ='Comps Data'!H13 -> 1287.32 | G25: ='Comps Data'!V13 -> 0.22847323 | H25: =F25/E25 -> 0.016897416 | I25: =F25/SUM(E25:F25) -> 0.016616638 | J25: =H15 -> 0.91028497 | K25: =J25/(1+(1-G25)*H25) -> 0.89857047
F27: Average | G27: =AVERAGE(G20:G25) -> 0.23821534 | H27: =AVERAGE(H20:H25) -> 0.013325898 | I27: =AVERAGE(I20:I25) -> 0.012983656 | J27: =AVERAGE(J20:J25) -> 0.95980806 | K27: =AVERAGE(K20:K25) -> 0.95019575
F28: Median | G28: =MEDIAN(G20:G25) -> 0.23303099 | H28: =MEDIAN(H20:H25) -> 0.0088217864 | I28: =MEDIAN(I20:I25) -> 0.0087408724 | J28: =MEDIAN(J20:J25) -> 0.95405317 | K28: =MEDIAN(K20:K25) -> 0.94891811
B30: Notes:
B31: The weight for adjusted beta taken from Bloomberg 2026 data.
B32: The comps tax rate has been calculated by Tax Amount/EBT for last Year
B33: Standalone Blume-adjusted beta (0.90) used rather than peer-comps beta (0.95), as ITC's diversified conglomerate structure (cigarettes, FMCG, agri, paperboards) makes pure-play FMCG peers imperfectly comparable.

Sheet SOTP>

Sheet SOTP - Valuation
B1: ='Data Sheet'!B1 -> ITC LTD
B2: SOTP
B4: Calculation of SOTP
B6: Segment | C6: Metric Used | D6: Multiple Source | E6: Metric Value | F6: Multiple | G6: Segment EV
B7: Cigarettes | C7: EBITDA | D7: Godfrey Phillips, Comps Data | E7: ='SOTP - Segment Data'!H3 -> 21315.18 | F7: {=MEDIAN(IF('Comps Data'!$D$5:$D$22=B7,'Comps Data'!$P$5:$P$22))} -> 16.066213 | G7: =E7*F7 -> 342454.22
B8: FMCG-Others | C8: Total Revenue | D8: Median of 7-peer EV/Sales | E8: ='SOTP - Segment Data'!E4 -> 24209.75 | F8: {=MEDIAN(IF('Comps Data'!$D$5:$D$22=B8,'Comps Data'!$Q$5:$Q$22))} -> 7.6203708 | G8: =E8*F8 -> 184487.27
B9: Agri Business | C9: External Revenue | D9: AWL Agri Business EV/Sales | E9: ='SOTP - Segment Data'!C5 -> 12296.48 | F9: {=MEDIAN(IF('Comps Data'!$D$5:$D$22=B9,'Comps Data'!$Q$5:$Q$22))} -> 0.30041922 | G9: =E9*F9 -> 3694.0989
B10: Paperboards | C10: EBITDA | D10: Median of 3-peer EV/EBITDA | E10: ='SOTP - Segment Data'!H6 -> 1187.1 | F10: {=MEDIAN(IF('Comps Data'!$D$5:$D$22=B10,'Comps Data'!$P$5:$P$22))} -> 8.2846754 | G10: =E10*F10 -> 9834.7382
B11: Others | C11: - | D11: Net segment assets (Assets - Liabilities) | F11: 0 | G11: 159.71
B13: Sum of Segment Evs | G13: =SUM(G7:G11) -> 540630.04
B14: Less: Unallocated corporate costs adjustment | G14: =('Master Input Center'!C46*(1-'Master Input Center'!C4))/'Master Input Center'!C47 -> 8784.9047
B15: Total Enterprise Value (SOTP) | G15: =G13-G14 -> 531845.14
B16: Add : Cash | G16: =DCF!I25 -> 3009
B17: Add : Investments | G17: =DCF!I26 -> 38128
B18: Less : Debt | G18: =DCF!I27 -> 2186
B19: Value of Equity | G19: =G15+G16+G17-G18 -> 570796.14
B20: No.of Shares | G20: =DCF!I29 -> 1252.95
B22: SOTP Value Per Share | G22: =G19/G20 -> 455.56179
B24: Share Price | G24: =DCF!I33 -> 268
B25: =IF(G24>G22,"Premium","Discount") -> Discount | G25: =IF(G22>G24,1-(G24/G22),IF(G22<G24,(G24/G22)-1,0)) -> 0.41171536
B27: SOTP Methodology Note
B29: Basis: Segment Revenue/EBIT/D&A from ITC FY2026 Annual Report, Note 30.
B31: Method by segment:
B33: 1. Cigarettes — EV/EBITDA 16.1x (Godfrey Phillips, sole peer). Stable, high-margin.
B34: 2. FMCG–Others — EV/Sales 7.6x (median: HUL, Nestlé, Britannia, Marico, Godrej Consumer, Dabur, Colgate). EV/Sales used, not EV/EBITDA, since segment EBITDA margin (~10%) is depressed by brand-building/gestation costs per the segment note — not representative of steady-state profitability. Alcohol/bottling/tea peers excluded (no equivalent business in this segment).
B35: 3. Agri Business - EV/Sales 0.30x (AWL Agri, sole peer), applied to external revenue only - excludes inter-segment leaf-tobacco transfers to Cigarettes.
B36: 4. Paperboards — EV/EBITDA 8.28x (median: JK Paper, West Coast Paper, Seshasayee). Andhra Paper excluded — outlier multiple from temporarily depressed earnings, not a real premium.
B37: 5. Others — Net segment assets (₹159.71 Cr); EBIT negative and segment immaterial (<0.5% of revenue).
B38: 6. Unallocated corporate cost: ₹1,228.83 Cr capitalized as a perpetuity (Cost × (1–Tax)/WACC), not subtracted once, since it recurs indefinitely. Tax and WACC linked to the same DCF assumptions.
B39: 7. Limitations: Cigarettes and Agri each rest on a single peer. Sensitivity testing shows Cigarettes drives the output materially (±30% multiple ˜ ±₹80–90/share); Agri is immaterial (<₹1/share) due to its small scale. WACC/Tax swings affect the output by <1%.
B40: 8. vs. DCF: SOTP (₹455.6/share) exceeds DCF (₹223.60/share) because DCF applies one blended growth/discount profile to segments with very different real profiles (mature Cigarettes vs. early-stage FMCG–Others). Read as a conglomerate-discount signal, consistent with the ~41% gap to current market price — not a contradiction between methods.

Sheet Data>

Sheet Altman's Z Score
B2: ='Data Sheet'!B1 -> ITC LTD
B3: Altman's Z Score Analysis Charts
B45: ='Data Sheet'!B1 -> ITC LTD
B46: Altman's Z Score Analysis
B47: Particulars | D47: ='Common Size Statements'!G$4 -> 44286 | E47: ='Common Size Statements'!H$4 -> 44651 | F47: ='Common Size Statements'!I$4 -> 45016 | G47: ='Common Size Statements'!J$4 -> 45382 | H47: ='Common Size Statements'!K$4 -> 45747 | I47: ='Common Size Statements'!L$4 -> 46112
B49: Working Capital / Total Asset (A)
B51: Working Capital | D51: ='Intrinsic Growth'!C23 -> 3777 | E51: ='Intrinsic Growth'!D23 -> 5753 | F51: ='Intrinsic Growth'!E23 -> 6311 | G51: ='Intrinsic Growth'!F23 -> 5797 | H51: ='Intrinsic Growth'!G23 -> 8538 | I51: ='Intrinsic Growth'!H23 -> 9724
B52: Total Asset | D52: ='Historicals FS'!G71 -> 73760.76 | E52: ='Historicals FS'!H71 -> 77196.02 | F52: ='Historicals FS'!I71 -> 85830.96 | G52: ='Historicals FS'!J71 -> 91753.97 | H52: ='Historicals FS'!K71 -> 88002.7 | I52: ='Historicals FS'!L71 -> 93637.2
B54: =B49 -> Working Capital / Total Asset (A) | D54: =D51/D52 -> 0.051206088 | E54: =E51/E52 -> 0.074524567 | F54: =F51/F52 -> 0.073528247 | G54: =G51/G52 -> 0.063179828 | H54: =H51/H52 -> 0.097019751 | I54: =I51/I52 -> 0.10384762
B56: Retained Earnings / Total Asset (B)
B57: Particulars | D57: ='Common Size Statements'!G$4 -> 44286 | E57: ='Common Size Statements'!H$4 -> 44651 | F57: ='Common Size Statements'!I$4 -> 45016 | G57: ='Common Size Statements'!J$4 -> 45382 | H57: ='Common Size Statements'!K$4 -> 45747 | I57: ='Common Size Statements'!L$4 -> 46112
B59: Retained Earnings | D59: ='Historicals FS'!G57 -> 59116.46 | E59: ='Historicals FS'!H57 -> 61223.24 | F59: ='Historicals FS'!I57 -> 67912.46 | G59: ='Historicals FS'!J57 -> 73258.53 | H59: ='Historicals FS'!K57 -> 68778.64 | I59: ='Historicals FS'!L57 -> 71254.35
B60: Total Assets | D60: =D52 -> 73760.76 | E60: =E52 -> 77196.02 | F60: =F52 -> 85830.96 | G60: =G52 -> 91753.97 | H60: =H52 -> 88002.7 | I60: =I52 -> 93637.2
B62: =B56 -> Retained Earnings / Total Asset (B) | D62: =D59/D60 -> 0.80146219 | E62: =E59/E60 -> 0.79308804 | F62: =F59/F60 -> 0.791235 | G62: =G59/G60 -> 0.79842355 | H62: =H59/H60 -> 0.78155148 | I62: =I59/I60 -> 0.76096199
B64: EBIT / Total Asset (C)
B65: Particulars | D65: ='Common Size Statements'!G$4 -> 44286 | E65: ='Common Size Statements'!H$4 -> 44651 | F65: ='Common Size Statements'!I$4 -> 45016 | G65: ='Common Size Statements'!J$4 -> 45382 | H65: ='Common Size Statements'!K$4 -> 45747 | I65: ='Common Size Statements'!L$4 -> 46112
B67: EBIT | D67: ='Historicals FS'!G23 -> 15419.19 | E67: ='Historicals FS'!H23 -> 18890.74 | F67: ='Historicals FS'!I23 -> 23895.25 | G67: ='Historicals FS'!J23 -> 23669.48 | H67: ='Historicals FS'!K23 -> 24185.26 | I67: ='Historicals FS'!L23 -> 25595.47
B68: Total Asset | D68: =D52 -> 73760.76 | E68: =E52 -> 77196.02 | F68: =F52 -> 85830.96 | G68: =G52 -> 91753.97 | H68: =H52 -> 88002.7 | I68: =I52 -> 93637.2
B70: =B64 -> EBIT / Total Asset (C) | D70: =D67/D68 -> 0.20904326 | E70: =E67/E68 -> 0.24471132 | F70: =F67/F68 -> 0.27839896 | G70: =G67/G68 -> 0.25796682 | H70: =H67/H68 -> 0.27482407 | I70: =I67/I68 -> 0.27334724
B72: Market Cap. / Total Liabilities (D)
B73: Particulars | D73: ='Common Size Statements'!G$4 -> 44286 | E73: ='Common Size Statements'!H$4 -> 44651 | F73: ='Common Size Statements'!I$4 -> 45016 | G73: ='Common Size Statements'!J$4 -> 45382 | H73: ='Common Size Statements'!K$4 -> 45747 | I73: ='Common Size Statements'!L$4 -> 46112
B75: Market Cap. | D75: ='Data Sheet'!F90*'Data Sheet'!F93 -> 252108.84 | E75: ='Data Sheet'!G90*'Data Sheet'!G93 -> 289548.26 | F75: ='Data Sheet'!H90*'Data Sheet'!H93 -> 446774.17 | G75: ='Data Sheet'!I90*'Data Sheet'!I93 -> 501298.16 | H75: ='Data Sheet'!J90*'Data Sheet'!J93 -> 512765.25 | I75: ='Data Sheet'!K90*'Data Sheet'!K93 -> 360473.72
B76: Total Liabilities | D76: =SUM('Historicals FS'!G58:G59) -> 13413.42 | E76: =SUM('Historicals FS'!H58:H59) -> 14740.45 | F76: =SUM('Historicals FS'!I58:I59) -> 16675.7 | G76: =SUM('Historicals FS'!J58:J59) -> 17246.97 | H76: =SUM('Historicals FS'!K58:K59) -> 17972.65 | I76: =SUM('Historicals FS'!L58:L59) -> 21129.9
B78: =B72 -> Market Cap. / Total Liabilities (D) | D78: =D75/D76 -> 18.795269 | E78: =E75/E76 -> 19.643108 | F78: =F75/F76 -> 26.791929 | G78: =G75/G76 -> 29.065868 | H78: =H75/H76 -> 28.530308 | I78: =I75/I76 -> 17.059887
B80: Sales / Total Asset (E)
B81: Particulars | D81: ='Common Size Statements'!G$4 -> 44286 | E81: ='Common Size Statements'!H$4 -> 44651 | F81: ='Common Size Statements'!I$4 -> 45016 | G81: ='Common Size Statements'!J$4 -> 45382 | H81: ='Common Size Statements'!K$4 -> 45747 | I81: ='Common Size Statements'!L$4 -> 46112
B83: Sales | D83: ='Historicals FS'!G5 -> 49257.45 | E83: ='Historicals FS'!H5 -> 60644.54 | F83: ='Historicals FS'!I5 -> 70919.03 | G83: ='Historicals FS'!J5 -> 67931.94 | H83: ='Historicals FS'!K5 -> 75323.34 | I83: ='Historicals FS'!L5 -> 78868.4
B84: Total Asset | D84: =D52 -> 73760.76 | E84: =E52 -> 77196.02 | F84: =F52 -> 85830.96 | G84: =G52 -> 91753.97 | H84: =H52 -> 88002.7 | I84: =I52 -> 93637.2
B86: =B80 -> Sales / Total Asset (E) | D86: =D83/D84 -> 0.6678002 | E86: =E83/E84 -> 0.78559154 | F86: =F83/F84 -> 0.82626397 | G86: =G83/G84 -> 0.74037058 | H86: =H83/H84 -> 0.85592078 | I86: =I83/I84 -> 0.84227636
B88: Altman's Z Score Table
B89: Particulars | C89: Weight | D89: ='Common Size Statements'!G$4 -> 44286 | E89: ='Common Size Statements'!H$4 -> 44651 | F89: ='Common Size Statements'!I$4 -> 45016 | G89: ='Common Size Statements'!J$4 -> 45382 | H89: ='Common Size Statements'!K$4 -> 45747 | I89: ='Common Size Statements'!L$4 -> 46112
B91: =B54 -> Working Capital / Total Asset (A) | C91: ='Master Input Center'!C39 -> 1.2 | D91: =D54*$C$91 -> 0.061447306 | E91: =E54*$C$91 -> 0.089429481 | F91: =F54*$C$91 -> 0.088233896 | G91: =G54*$C$91 -> 0.075815793 | H91: =H54*$C$91 -> 0.1164237 | I91: =I54*$C$91 -> 0.12461714
B92: =B62 -> Retained Earnings / Total Asset (B) | C92: ='Master Input Center'!C40 -> 1.4 | D92: =D62*$C$92 -> 1.1220471 | E92: =E62*$C$92 -> 1.1103233 | F92: =F62*$C$92 -> 1.107729 | G92: =G62*$C$92 -> 1.117793 | H92: =H62*$C$92 -> 1.0941721 | I92: =I62*$C$92 -> 1.0653468
B93: =B70 -> EBIT / Total Asset (C) | C93: ='Master Input Center'!C41 -> 3.3 | D93: =D70*$C$93 -> 0.68984277 | E93: =E70*$C$93 -> 0.80754736 | F93: =F70*$C$93 -> 0.91871657 | G93: =G70*$C$93 -> 0.85129051 | H93: =H70*$C$93 -> 0.90691942 | I93: =I70*$C$93 -> 0.90204589
B94: =B78 -> Market Cap. / Total Liabilities (D) | C94: ='Master Input Center'!C42 -> 0.6 | D94: =D78*$C$94 -> 11.277162 | E94: =E78*$C$94 -> 11.785865 | F94: =F78*$C$94 -> 16.075157 | G94: =G78*$C$94 -> 17.439521 | H94: =H78*$C$94 -> 17.118185 | I94: =I78*$C$94 -> 10.235932
B95: =B86 -> Sales / Total Asset (E) | C95: ='Master Input Center'!C43 -> 1 | D95: =D86*$C$95 -> 0.6678002 | E95: =E86*$C$95 -> 0.78559154 | F95: =F86*$C$95 -> 0.82626397 | G95: =G86*$C$95 -> 0.74037058 | H95: =H86*$C$95 -> 0.85592078 | I95: =I86*$C$95 -> 0.84227636
B97: Altman's Z Score | D97: =SUM(D91:D95) -> 13.818299 | E97: =SUM(E91:E95) -> 14.578757 | F97: =SUM(F91:F95) -> 19.016101 | G97: =SUM(G91:G95) -> 20.224791 | H97: =SUM(H91:H95) -> 20.091621 | I97: =SUM(I91:I95) -> 13.170219
B99: Financial Stability | D99: =IF(AND(D97<=2.99,D97>=1.81)," Distressed ",IF(D97>=3," Strong "," Grey Zone ")) -> Strong | E99: =IF(AND(E97<=2.99,E97>=1.81)," Distressed ",IF(E97>=3," Strong "," Grey Zone ")) -> Strong | F99: =IF(AND(F97<=2.99,F97>=1.81)," Distressed ",IF(F97>=3," Strong "," Grey Zone ")) -> Strong | G99: =IF(AND(G97<=2.99,G97>=1.81)," Distressed ",IF(G97>=3," Strong "," Grey Zone ")) -> Strong | H99: =IF(AND(H97<=2.99,H97>=1.81)," Distressed ",IF(H97>=3," Strong "," Grey Zone ")) -> Strong | I99: =IF(AND(I97<=2.99,I97>=1.81)," Distressed ",IF(I97>=3," Strong "," Grey Zone ")) -> Strong

Sheet DuPont Analysis
B2: ='Data Sheet'!B1 -> ITC LTD
B3: DuPont Analysis Charts
B33: Return on Equity (ROE)
B34: Particulars | D34: ='Common Size Statements'!F4 -> 43921 | E34: ='Common Size Statements'!G4 -> 44286 | F34: ='Common Size Statements'!H4 -> 44651 | G34: ='Common Size Statements'!I4 -> 45016 | H34: ='Common Size Statements'!J4 -> 45382 | I34: ='Common Size Statements'!K4 -> 45747 | J34: ='Common Size Statements'!L4 -> 46112
B36: Net Profit | D36: ='Historicals FS'!F36 -> 13175.46 | E36: ='Historicals FS'!G36 -> 10805.93 | F36: ='Historicals FS'!H36 -> 13593.41 | G36: ='Historicals FS'!I36 -> 17379.08 | H36: ='Historicals FS'!J36 -> 17420.91 | I36: ='Historicals FS'!K36 -> 17249.73 | J36: ='Historicals FS'!L36 -> 18495.06
B37: Average Shareholders Equity | D37: =(SUM('Historicals FS'!F56:F57)+SUM('Historicals FS'!E56:E57))/2 -> 62207.065 | E37: =(SUM('Historicals FS'!G56:G57)+SUM('Historicals FS'!F56:F57))/2 -> 62810.3 | F37: =(SUM('Historicals FS'!H56:H57)+SUM('Historicals FS'!G56:G57))/2 -> 61401.455 | G37: =(SUM('Historicals FS'!I56:I57)+SUM('Historicals FS'!H56:H57))/2 -> 65805.415 | H37: =(SUM('Historicals FS'!J56:J57)+SUM('Historicals FS'!I56:I57))/2 -> 71831.13 | I37: =(SUM('Historicals FS'!K56:K57)+SUM('Historicals FS'!J56:J57))/2 -> 72268.525 | J37: =(SUM('Historicals FS'!L56:L57)+SUM('Historicals FS'!K56:K57))/2 -> 71268.675
B39: Return on Equity | D39: =D36/D37 -> 0.21180006 | E39: =E36/E37 -> 0.17204073 | F39: =F36/F37 -> 0.2213858 | G39: =G36/G37 -> 0.26409802 | H39: =H36/H37 -> 0.24252591 | I39: =I36/I37 -> 0.23868939 | J39: =J36/J37 -> 0.25951177
B41: ROE DuPont Analysis
B42: Particulars | D42: ='Common Size Statements'!F4 -> 43921 | E42: ='Common Size Statements'!G4 -> 44286 | F42: ='Common Size Statements'!H4 -> 44651 | G42: ='Common Size Statements'!I4 -> 45016 | H42: ='Common Size Statements'!J4 -> 45382 | I42: ='Common Size Statements'!K4 -> 45747 | J42: ='Common Size Statements'!L4 -> 46112
B44: Net Profit | D44: =D36 -> 13175.46 | E44: =E36 -> 10805.93 | F44: =F36 -> 13593.41 | G44: =G36 -> 17379.08 | H44: =H36 -> 17420.91 | I44: =I36 -> 17249.73 | J44: =J36 -> 18495.06
B45: Revenue | D45: ='Historicals FS'!F5 -> 49387.7 | E45: ='Historicals FS'!G5 -> 49257.45 | F45: ='Historicals FS'!H5 -> 60644.54 | G45: ='Historicals FS'!I5 -> 70919.03 | H45: ='Historicals FS'!J5 -> 67931.94 | I45: ='Historicals FS'!K5 -> 75323.34 | J45: ='Historicals FS'!L5 -> 78868.4
B47: Net Profit Margins (A) | D47: =D44/D45 -> 0.26677614 | E47: =E44/E45 -> 0.21937656 | F47: =F44/F45 -> 0.22414895 | G47: =G44/G45 -> 0.24505524 | H47: =H44/H45 -> 0.25644653 | I47: =I44/I45 -> 0.2290091 | J47: =J44/J45 -> 0.23450533
B49: Revenue | D49: =D45 -> 49387.7 | E49: =E45 -> 49257.45 | F49: =F45 -> 60644.54 | G49: =G45 -> 70919.03 | H49: =H45 -> 67931.94 | I49: =I45 -> 75323.34 | J49: =J45 -> 78868.4
B50: Average Total Asset | D50: =SUM('Historicals FS'!E71:F71) -> 149049.79 | E50: =SUM('Historicals FS'!F71:G71) -> 151071.51 | F50: =SUM('Historicals FS'!G71:H71) -> 150956.78 | G50: =SUM('Historicals FS'!H71:I71) -> 163026.98 | H50: =SUM('Historicals FS'!I71:J71) -> 177584.93 | I50: =SUM('Historicals FS'!J71:K71) -> 179756.67 | J50: =SUM('Historicals FS'!K71:L71) -> 181639.9
B52: Asset Turnover Ratio (B) | D52: =D49/D50 -> 0.33135035 | E52: =E49/E50 -> 0.32605387 | F52: =F49/F50 -> 0.40173446 | G52: =G49/G50 -> 0.43501407 | H52: =H49/H50 -> 0.38253212 | I52: =I49/I50 -> 0.41902946 | J52: =J49/J50 -> 0.43420196
B54: Average Total Asset | D54: =D50 -> 149049.79 | E54: =E50 -> 151071.51 | F54: =F50 -> 150956.78 | G54: =G50 -> 163026.98 | H54: =H50 -> 177584.93 | I54: =I50 -> 179756.67 | J54: =J50 -> 181639.9
B55: Average Shareholders Equity | D55: =D37 -> 62207.065 | E55: =E37 -> 62810.3 | F55: =F37 -> 61401.455 | G55: =G37 -> 65805.415 | H55: =H37 -> 71831.13 | I55: =I37 -> 72268.525 | J55: =J37 -> 71268.675
B57: Equity Multiplier (C) | D57: =D54/D55 -> 2.3960267 | E57: =E54/E55 -> 2.4052028 | F57: =F54/F55 -> 2.4585212 | G57: =G54/G55 -> 2.4774098 | H57: =H54/H55 -> 2.4722558 | I57: =I54/I55 -> 2.4873438 | J57: =J54/J55 -> 2.5486639
B59: ROE (A*B*C) | D59: =D47*D52*D57 -> 0.21180006 | E59: =E47*E52*E57 -> 0.17204073 | F59: =F47*F52*F57 -> 0.2213858 | G59: =G47*G52*G57 -> 0.26409802 | H59: =H47*H52*H57 -> 0.24252591 | I59: =I47*I52*I57 -> 0.23868939 | J59: =J47*J52*J57 -> 0.25951177
D60: =D39=D59 -> TRUE | E60: =E39=E59 -> TRUE | F60: =F39=F59 -> TRUE | G60: =G39=G59 -> TRUE | H60: =H39=H59 -> TRUE | I60: =I39=I59 -> TRUE | J60: =J39=J59 -> TRUE
B62: Return on Assets (ROA)
B63: Particulars | D63: ='Common Size Statements'!F4 -> 43921 | E63: ='Common Size Statements'!G4 -> 44286 | F63: ='Common Size Statements'!H4 -> 44651 | G63: ='Common Size Statements'!I4 -> 45016 | H63: ='Common Size Statements'!J4 -> 45382 | I63: ='Common Size Statements'!K4 -> 45747 | J63: ='Common Size Statements'!L4 -> 46112
B65: Net Profit | D65: =D44 -> 13175.46 | E65: =E44 -> 10805.93 | F65: =F44 -> 13593.41 | G65: =G44 -> 17379.08 | H65: =H44 -> 17420.91 | I65: =I44 -> 17249.73 | J65: =J44 -> 18495.06
B66: Average Total Asset | D66: =D50 -> 149049.79 | E66: =E50 -> 151071.51 | F66: =F50 -> 150956.78 | G66: =G50 -> 163026.98 | H66: =H50 -> 177584.93 | I66: =I50 -> 179756.67 | J66: =J50 -> 181639.9
B68: Return on Asset(ROA) | D68: =D65/D66 -> 0.088396367 | E68: =E65/E66 -> 0.071528576 | F68: =F65/F66 -> 0.090048357 | G68: =G65/G66 -> 0.10660248 | H68: =H65/H66 -> 0.098099034 | I68: =I65/I66 -> 0.095961557 | J68: =J65/J66 -> 0.10182267
B70: ROA - DuPont Analysis
B71: Particulars | D71: ='Common Size Statements'!F24 -> 43921 | E71: ='Common Size Statements'!G24 -> 44286 | F71: ='Common Size Statements'!H24 -> 44651 | G71: ='Common Size Statements'!I24 -> 45016 | H71: ='Common Size Statements'!J24 -> 45382 | I71: ='Common Size Statements'!K24 -> 45747 | J71: ='Common Size Statements'!L24 -> 46112
B73: Net Profit | D73: =D44 -> 13175.46 | E73: =E44 -> 10805.93 | F73: =F44 -> 13593.41 | G73: =G44 -> 17379.08 | H73: =H44 -> 17420.91 | I73: =I44 -> 17249.73 | J73: =J44 -> 18495.06
B74: Revenue | D74: =D45 -> 49387.7 | E74: =E45 -> 49257.45 | F74: =F45 -> 60644.54 | G74: =G45 -> 70919.03 | H74: =H45 -> 67931.94 | I74: =I45 -> 75323.34 | J74: =J45 -> 78868.4
B76: Net Profit Margins (A) | D76: =D73/D74 -> 0.26677614 | E76: =E73/E74 -> 0.21937656 | F76: =F73/F74 -> 0.22414895 | G76: =G73/G74 -> 0.24505524 | H76: =H73/H74 -> 0.25644653 | I76: =I73/I74 -> 0.2290091 | J76: =J73/J74 -> 0.23450533
B78: Revenue | D78: =D49 -> 49387.7 | E78: =E49 -> 49257.45 | F78: =F49 -> 60644.54 | G78: =G49 -> 70919.03 | H78: =H49 -> 67931.94 | I78: =I49 -> 75323.34 | J78: =J49 -> 78868.4
B79: Average Total Asset | D79: =D50 -> 149049.79 | E79: =E50 -> 151071.51 | F79: =F50 -> 150956.78 | G79: =G50 -> 163026.98 | H79: =H50 -> 177584.93 | I79: =I50 -> 179756.67 | J79: =J50 -> 181639.9
B81: Asset Turnover Ratio (B) | D81: =D78/D79 -> 0.33135035 | E81: =E78/E79 -> 0.32605387 | F81: =F78/F79 -> 0.40173446 | G81: =G78/G79 -> 0.43501407 | H81: =H78/H79 -> 0.38253212 | I81: =I78/I79 -> 0.41902946 | J81: =J78/J79 -> 0.43420196
B83: Return on Asset (A*B) | D83: =D81*D76 -> 0.088396367 | E83: =E81*E76 -> 0.071528576 | F83: =F81*F76 -> 0.090048357 | G83: =G81*G76 -> 0.10660248 | H83: =H81*H76 -> 0.098099034 | I83: =I81*I76 -> 0.095961557 | J83: =J81*J76 -> 0.10182267
D84: =D68=D83 -> TRUE | E84: =E68=E83 -> TRUE | F84: =F68=F83 -> TRUE | G84: =G68=G83 -> TRUE | H84: =H68=H83 -> TRUE | I84: =I68=I83 -> TRUE | J84: =J68=J83 -> TRUE

Sheet Ratio Analysis
B4: ="Ratio Analysis "&'Data Sheet'!B1 -> Ratio Analysis ITC LTD
B5: Particulars | C5: =IFERROR('Data Sheet'!B16,_xleta.NA) -> 42825 | D5: =IFERROR('Data Sheet'!C16,_xleta.NA) -> 43190 | E5: =IFERROR('Data Sheet'!D16,_xleta.NA) -> 43555 | F5: =IFERROR('Data Sheet'!E16,_xleta.NA) -> 43921 | G5: =IFERROR('Data Sheet'!F16,_xleta.NA) -> 44286 | H5: =IFERROR('Data Sheet'!G16,_xleta.NA) -> 44651 | I5: =IFERROR('Data Sheet'!H16,_xleta.NA) -> 45016 | J5: =IFERROR('Data Sheet'!I16,_xleta.NA) -> 45382 | ... L5: =IFERROR('Data Sheet'!K16,_xleta.NA) -> 46112 | M5: Trend Line | N5: Mean | O5: Median
B7: Revenue (Y-o-Y) Growth | C7: 0 | D7: ='Historicals FS'!D6 -> 0.015931219 | E7: ='Historicals FS'!E6 -> 0.11256063 | F7: ='Historicals FS'!F6 -> 0.021682439 | G7: ='Historicals FS'!G6 -> -0.0026372963 | H7: ='Historicals FS'!H6 -> 0.23117498 | I7: ='Historicals FS'!I6 -> 0.16942152 | J7: ='Historicals FS'!J6 -> -0.042119724 | K7: ='Historicals FS'!K6 -> 0.10880596 | L7: ='Historicals FS'!L6 -> 0.047064562 | N7: =AVERAGE(D7:L7) -> 0.073542698 | O7: =MEDIAN(D7:L7) -> 0.047064562
B8: Gross Profit (Y-o-Y) Growth | C8: 0 | D8: =IFERROR(('Historicals FS'!D11/'Historicals FS'!C11)-1,0) -> 0.031844784 | E8: =IFERROR(('Historicals FS'!E11/'Historicals FS'!D11)-1,0) -> 0.12299874 | F8: =IFERROR(('Historicals FS'!F11/'Historicals FS'!E11)-1,0) -> 0.038703545 | G8: =IFERROR(('Historicals FS'!G11/'Historicals FS'!F11)-1,0) -> -0.10700914 | H8: =IFERROR(('Historicals FS'!H11/'Historicals FS'!G11)-1,0) -> 0.18839611 | I8: =IFERROR(('Historicals FS'!I11/'Historicals FS'!H11)-1,0) -> 0.22659213 | J8: =IFERROR(('Historicals FS'!J11/'Historicals FS'!I11)-1,0) -> -0.01075976 | K8: =IFERROR(('Historicals FS'!K11/'Historicals FS'!J11)-1,0) -> 0.049221548 | L8: =IFERROR(('Historicals FS'!L11/'Historicals FS'!K11)-1,0) -> 0.063646592 | N8: =AVERAGE(D8:L8) -> 0.067070505 | O8: =MEDIAN(D8:L8) -> 0.049221548
B9: EBITDA (Y-o-Y) Growth | C9: 0 | D9: =IFERROR(('Historicals FS'!D17/'Historicals FS'!C17)-1,0) -> 0.067945268 | E9: =IFERROR(('Historicals FS'!E17/'Historicals FS'!D17)-1,0) -> 0.12207796 | F9: =IFERROR(('Historicals FS'!F17/'Historicals FS'!E17)-1,0) -> 0.043487783 | G9: =IFERROR(('Historicals FS'!G17/'Historicals FS'!F17)-1,0) -> -0.1178047 | H9: =IFERROR(('Historicals FS'!H17/'Historicals FS'!G17)-1,0) -> 0.20852129 | I9: =IFERROR(('Historicals FS'!I17/'Historicals FS'!H17)-1,0) -> 0.24637895 | J9: =IFERROR(('Historicals FS'!J17/'Historicals FS'!I17)-1,0) -> -0.020102893 | K9: =IFERROR(('Historicals FS'!K17/'Historicals FS'!J17)-1,0) -> 0.025570193 | L9: =IFERROR(('Historicals FS'!L17/'Historicals FS'!K17)-1,0) -> 0.057078197 | N9: =AVERAGE(D9:L9) -> 0.070350228 | O9: =MEDIAN(D9:L9) -> 0.057078197
B10: EBIT (Y-o-Y) Growth | C10: 0 | D10: =IFERROR(('Historicals FS'!D23/'Historicals FS'!C23)-1,0) -> 0.067584614 | E10: =IFERROR(('Historicals FS'!E23/'Historicals FS'!D23)-1,0) -> 0.12146247 | F10: =IFERROR(('Historicals FS'!F23/'Historicals FS'!E23)-1,0) -> 0.032545193 | G10: =IFERROR(('Historicals FS'!G23/'Historicals FS'!F23)-1,0) -> -0.12879189 | H10: =IFERROR(('Historicals FS'!H23/'Historicals FS'!G23)-1,0) -> 0.22514477 | I10: =IFERROR(('Historicals FS'!I23/'Historicals FS'!H23)-1,0) -> 0.26491869 | J10: =IFERROR(('Historicals FS'!J23/'Historicals FS'!I23)-1,0) -> -0.0094483213 | K10: =IFERROR(('Historicals FS'!K23/'Historicals FS'!J23)-1,0) -> 0.021790931 | L10: =IFERROR(('Historicals FS'!L23/'Historicals FS'!K23)-1,0) -> 0.058308656 | N10: =AVERAGE(D10:L10) -> 0.07261279 | O10: =MEDIAN(D10:L10) -> 0.058308656
B11: EBT (Y-o-Y) Growth | C11: 0 | D11: =IFERROR(('Historicals FS'!D29/'Historicals FS'!C29)-1,0) -> 0.06319243 | E11: =IFERROR(('Historicals FS'!E29/'Historicals FS'!D29)-1,0) -> 0.12525825 | F11: =IFERROR(('Historicals FS'!F29/'Historicals FS'!E29)-1,0) -> 0.032096655 | G11: =IFERROR(('Historicals FS'!G29/'Historicals FS'!F29)-1,0) -> -0.12805801 | H11: =IFERROR(('Historicals FS'!H29/'Historicals FS'!G29)-1,0) -> 0.22586292 | I11: =IFERROR(('Historicals FS'!I29/'Historicals FS'!H29)-1,0) -> 0.26481845 | J11: =IFERROR(('Historicals FS'!J29/'Historicals FS'!I29)-1,0) -> -0.0078559948 | K11: =IFERROR(('Historicals FS'!K29/'Historicals FS'!J29)-1,0) -> 0.021575202 | L11: =IFERROR(('Historicals FS'!L29/'Historicals FS'!K29)-1,0) -> 0.056755951 | N11: =AVERAGE(D11:L11) -> 0.072627317 | O11: =MEDIAN(D11:L11) -> 0.056755951
B12: Net Profit (Y-o-Y) Growth | C12: 0 | D12: =IFERROR(('Historicals FS'!D36/'Historicals FS'!C36)-1,0) -> 0.061279334 | E12: =IFERROR(('Historicals FS'!E36/'Historicals FS'!D36)-1,0) -> 0.16239178 | F12: =IFERROR(('Historicals FS'!F36/'Historicals FS'!E36)-1,0) -> 0.225002 | G12: =IFERROR(('Historicals FS'!G36/'Historicals FS'!F36)-1,0) -> -0.1798442 | H12: =IFERROR(('Historicals FS'!H36/'Historicals FS'!G36)-1,0) -> 0.25795836 | I12: =IFERROR(('Historicals FS'!I36/'Historicals FS'!H36)-1,0) -> 0.27849303 | J12: =IFERROR(('Historicals FS'!J36/'Historicals FS'!I36)-1,0) -> 0.0024069168 | K12: =IFERROR(('Historicals FS'!K36/'Historicals FS'!J36)-1,0) -> -0.0098261227 | L12: =IFERROR(('Historicals FS'!L36/'Historicals FS'!K36)-1,0) -> 0.072194173 | N12: =AVERAGE(D12:L12) -> 0.096672809 | O12: =MEDIAN(D12:L12) -> 0.072194173
B13: Earnings Per Share (Y-o-Y) Growth | C13: 0 | D13: =IFERROR('Historicals FS'!D44,0) -> 0.056331341 | E13: =IFERROR('Historicals FS'!E44,0) -> 0.15724291 | F13: =IFERROR('Historicals FS'!F44,0) -> 0.22165353 | G13: =IFERROR('Historicals FS'!G44,0) -> -0.18095028 | H13: =IFERROR('Historicals FS'!H44,0) -> 0.25647821 | I13: =IFERROR('Historicals FS'!I44,0) -> 0.26772234 | J13: =IFERROR('Historicals FS'!J44,0) -> -0.0021455732 | K13: =IFERROR('Historicals FS'!K44,0) -> -0.012152388 | L13: =IFERROR('Historicals FS'!L44,0) -> 0.07087634 | N13: =AVERAGE(D13:L13) -> 0.092784047 | O13: =MEDIAN(D13:L13) -> 0.07087634
B14: Dividend Per Share (Y-o-Y) Growth | C14: 0 | D14: =IFERROR(('Historicals FS'!D46/'Historicals FS'!C46)-1,0) -> 0.084208811 | E14: =IFERROR(('Historicals FS'!E46/'Historicals FS'!D46)-1,0) -> 0.11650645 | F14: =IFERROR(('Historicals FS'!F46/'Historicals FS'!E46)-1,0) -> 0.76521571 | G14: =IFERROR(('Historicals FS'!G46/'Historicals FS'!F46)-1,0) -> 0.059113555 | H14: =IFERROR(('Historicals FS'!H46/'Historicals FS'!G46)-1,0) -> 0.069767819 | I14: =IFERROR(('Historicals FS'!I46/'Historicals FS'!H46)-1,0) -> 0.34782561 | J14: =IFERROR(('Historicals FS'!J46/'Historicals FS'!I46)-1,0) -> -0.11290335 | K14: =IFERROR(('Historicals FS'!K46/'Historicals FS'!J46)-1,0) -> 0.043636312 | L14: =IFERROR(('Historicals FS'!L46/'Historicals FS'!K46)-1,0) -> 0.010453437 | N14: =AVERAGE(D14:L14) -> 0.15375826 | O14: =MEDIAN(D14:L14) -> 0.069767819
B16: Gross Margins | C16: ='Historicals FS'!C12 -> 0.48678158 | D16: ='Historicals FS'!D12 -> 0.49440654 | E16: ='Historicals FS'!E12 -> 0.49904509 | F16: ='Historicals FS'!F12 -> 0.50735912 | G16: ='Historicals FS'!G12 -> 0.45426509 | H16: ='Historicals FS'!H12 -> 0.43848102 | I16: ='Historicals FS'!I12 -> 0.45991746 | J16: ='Historicals FS'!J12 -> 0.47497466 | ... L16: ='Historicals FS'!L12 -> 0.45656854 | N16: =AVERAGE(C16:L16) -> 0.47212498 | O16: =MEDIAN(C16:L16) -> 0.46744606
B17: EBITDA Margins | C17: ='Historicals FS'!C18 -> 0.36171097 | D17: ='Historicals FS'!D18 -> 0.38022999 | E17: ='Historicals FS'!E18 -> 0.38348265 | F17: ='Historicals FS'!F18 -> 0.39166716 | G17: ='Historicals FS'!G18 -> 0.34644059 | H17: ='Historicals FS'!H18 -> 0.34006606 | I17: ='Historicals FS'!I18 -> 0.36244517 | J17: ='Historicals FS'!J18 -> 0.37077596 | ... L17: ='Historicals FS'!L18 -> 0.34622231 | N17: =AVERAGE(C17:L17) -> 0.36259834 | O17: =MEDIAN(C17:L17) -> 0.36207807
B18: EBIT Margins | C18: ='Historicals FS'!C24 -> 0.33475622 | D18: ='Historicals FS'!D24 -> 0.35177636 | E18: ='Historicals FS'!E24 -> 0.354591 | F18: ='Historicals FS'!F24 -> 0.35836109 | G18: ='Historicals FS'!G24 -> 0.31303265 | H18: ='Historicals FS'!H24 -> 0.31149944 | I18: ='Historicals FS'!I24 -> 0.33693707 | J18: ='Historicals FS'!J24 -> 0.34842932 | ... L18: ='Historicals FS'!L24 -> 0.32453391 | N18: =AVERAGE(C18:L18) -> 0.33550029 | O18: =MEDIAN(C18:L18) -> 0.33584664
B19: EBT Margins | C19: ='Historicals FS'!C30 -> 0.33360979 | D19: ='Historicals FS'!D30 -> 0.34912935 | E19: ='Historicals FS'!E30 -> 0.35311395 | F19: ='Historicals FS'!F30 -> 0.35671331 | G19: ='Historicals FS'!G30 -> 0.31185577 | H19: ='Historicals FS'!H30 -> 0.31051023 | I19: ='Historicals FS'!I30 -> 0.33584046 | J19: ='Historicals FS'!J30 -> 0.3478536 | ... L19: ='Historicals FS'!L30 -> 0.32345401 | N19: =AVERAGE(C19:L19) -> 0.33425681 | O19: =MEDIAN(C19:L19) -> 0.33472513
B20: Net Margins | C20: ='Historicals FS'!C37 -> 0.20385993 | D20: ='Historicals FS'!D37 -> 0.21295963 | E20: ='Historicals FS'!E37 -> 0.222498 | F20: ='Historicals FS'!F37 -> 0.26677614 | G20: ='Historicals FS'!G37 -> 0.21937656 | H20: ='Historicals FS'!H37 -> 0.22414895 | I20: ='Historicals FS'!I37 -> 0.24505524 | J20: ='Historicals FS'!J37 -> 0.25644653 | ... L20: ='Historicals FS'!L37 -> 0.23450533 | N20: =AVERAGE(C20:L20) -> 0.23146354 | O20: =MEDIAN(C20:L20) -> 0.22657902
B22: COGS % of Sales | C22: ='Historicals FS'!C9 -> 0.51321842 | D22: ='Historicals FS'!D9 -> 0.50559346 | E22: ='Historicals FS'!E9 -> 0.50095491 | F22: ='Historicals FS'!F9 -> 0.49264088 | G22: ='Historicals FS'!G9 -> 0.54573491 | H22: ='Historicals FS'!H9 -> 0.56151898 | I22: ='Historicals FS'!I9 -> 0.54008254 | J22: ='Historicals FS'!J9 -> 0.52502534 | ... L22: ='Historicals FS'!L9 -> 0.54343146 | N22: =AVERAGE(C22:L22) -> 0.52787502 | O22: =MEDIAN(C22:L22) -> 0.53255394
B23: S&G Expenses % of Sales | C23: ='Historicals FS'!C15 -> 0.12507061 | D23: ='Historicals FS'!D15 -> 0.11417655 | E23: ='Historicals FS'!E15 -> 0.11556244 | F23: ='Historicals FS'!F15 -> 0.11569196 | G23: ='Historicals FS'!G15 -> 0.1078245 | H23: ='Historicals FS'!H15 -> 0.09841496 | I23: ='Historicals FS'!I15 -> 0.097472286 | J23: ='Historicals FS'!J15 -> 0.1041987 | ... L23: ='Historicals FS'!L15 -> 0.11034622 | N23: =AVERAGE(C23:L23) -> 0.10952664 | O23: =MEDIAN(C23:L23) -> 0.10908536
B24: Depreciaton % of Sales | C24: ='Historicals FS'!C21 -> 0.026954751 | D24: ='Historicals FS'!D21 -> 0.028453629 | E24: ='Historicals FS'!E21 -> 0.028891645 | F24: ='Historicals FS'!F21 -> 0.033306066 | G24: ='Historicals FS'!G21 -> 0.033407941 | H24: ='Historicals FS'!H21 -> 0.028566628 | I24: ='Historicals FS'!I21 -> 0.025508104 | J24: ='Historicals FS'!J21 -> 0.022346631 | ... L24: ='Historicals FS'!L21 -> 0.021688408 | N24: =AVERAGE(C24:L24) -> 0.027098051 | O24: =MEDIAN(C24:L24) -> 0.02770419
B25: Operating Income % of Sales | C25: =C18 -> 0.33475622 | D25: =D18 -> 0.35177636 | E25: =E18 -> 0.354591 | F25: =F18 -> 0.35836109 | G25: =G18 -> 0.31303265 | H25: =H18 -> 0.31149944 | I25: =I18 -> 0.33693707 | J25: =J18 -> 0.34842932 | ... L25: =L18 -> 0.32453391 | N25: =AVERAGE(C25:L25) -> 0.33550029 | O25: =MEDIAN(C25:L25) -> 0.33584664
B27: Return on Capital Employed (ROCE) | C27: =IFERROR('Historicals FS'!C23/SUM('Data Sheet'!B57:B59),0) -> 0.30816048 | D27: =IFERROR('Historicals FS'!D23/SUM('Data Sheet'!C57:C59),0) -> 0.29087469 | E27: =IFERROR('Historicals FS'!E23/SUM('Data Sheet'!D57:D59),0) -> 0.28976384 | F27: =IFERROR('Historicals FS'!F23/SUM('Data Sheet'!E57:E59),0) -> 0.26999906 | G27: =IFERROR('Historicals FS'!G23/SUM('Data Sheet'!F57:F59),0) -> 0.25436581 | H27: =IFERROR('Historicals FS'!H23/SUM('Data Sheet'!G57:G59),0) -> 0.30126365 | I27: =IFERROR('Historicals FS'!I23/SUM('Data Sheet'!H57:H59),0) -> 0.3440081 | J27: =IFERROR('Historicals FS'!J23/SUM('Data Sheet'!I57:I59),0) -> 0.31639278 | ... L27: =IFERROR('Historicals FS'!L23/SUM('Data Sheet'!K57:K59),0) -> 0.34169956 | N27: =AVERAGE(C27:L27) -> 0.30604859 | O27: =MEDIAN(C27:L27) -> 0.30471206
B28: Retained Earnings | C28: ='Historicals FS'!C49 -> 0.33819421 | D28: ='Historicals FS'!D49 -> 0.3207286 | E28: ='Historicals FS'!E49 -> 0.34463984 | F28: ='Historicals FS'!F49 -> 0.053044068 | G28: ='Historicals FS'!G49 -> 0 | H28: ='Historicals FS'!H49 -> 0 | I28: ='Historicals FS'!I49 -> 0 | J28: ='Historicals FS'!J49 -> 0.014606011 | ... L28: ='Historicals FS'!L49 -> 0.017695536 | N28: =AVERAGE(C28:L28) -> 0.10889083 | O28: =MEDIAN(C28:L28) -> 0.016150773
B29: Return on Equity (ROE) | C29: =IFERROR('Historicals FS'!C36/SUM('Data Sheet'!B57:B58),0) -> 0.18784852 | D29: =IFERROR('Historicals FS'!D36/SUM('Data Sheet'!C57:C58),0) -> 0.17621121 | E29: =IFERROR('Historicals FS'!E36/SUM('Data Sheet'!D57:D58),0) -> 0.18186171 | F29: =IFERROR('Historicals FS'!F36/SUM('Data Sheet'!E57:E58),0) -> 0.2018508 | G29: =IFERROR('Historicals FS'!G36/SUM('Data Sheet'!F57:F58),0) -> 0.17906224 | H29: =IFERROR('Historicals FS'!H36/SUM('Data Sheet'!G57:G58),0) -> 0.21764928 | I29: =IFERROR('Historicals FS'!I36/SUM('Data Sheet'!H57:H58),0) -> 0.25130525 | J29: =IFERROR('Historicals FS'!J36/SUM('Data Sheet'!I57:I58),0) -> 0.23381575 | ... L29: =IFERROR('Historicals FS'!L36/SUM('Data Sheet'!K57:K58),0) -> 0.25507859 | N29: =AVERAGE(C29:L29) -> 0.21310023 | O29: =MEDIAN(C29:L29) -> 0.20975004
B30: Self Sustained Growth Rate | C30: =C28*C29 -> 0.063529279 | D30: =D28*D29 -> 0.056515974 | E30: =E28*E29 -> 0.062676792 | F30: =F28*F29 -> 0.010706988 | G30: =G28*G29 -> 0 | H30: =H28*H29 -> 0 | I30: =I28*I29 -> 0 | J30: =J28*J29 -> 0.0034151154 | ... L30: =L28*L29 -> 0.0045137524 | N30: =AVERAGE(C30:L30) -> 0.02013579 | O30: =MEDIAN(C30:L30) -> 0.0039644339
B31: Interest Coverage Ratio | C31: ='Historicals FS'!C23/'Historicals FS'!C26 -> 291.99918 | D31: ='Historicals FS'!D23/'Historicals FS'!D26 -> 132.89549 | E31: ='Historicals FS'!E23/'Historicals FS'!E26 -> 240.06695 | F31: ='Historicals FS'!F23/'Historicals FS'!F26 -> 217.48132 | G31: ='Historicals FS'!G23/'Historicals FS'!G26 -> 265.98568 | H31: ='Historicals FS'!H23/'Historicals FS'!H26 -> 314.89815 | I31: ='Historicals FS'!I23/'Historicals FS'!I26 -> 307.25537 | J31: ='Historicals FS'!J23/'Historicals FS'!J26 -> 605.20276 | ... L31: ='Historicals FS'!L23/'Historicals FS'!L26 -> 300.52213 | N31: =AVERAGE(C31:L31) -> 321.30416 | O31: =MEDIAN(C31:L31) -> 296.26066
B33: Debtor Turnover Ratio | C33: =IFERROR('Historicals FS'!C5/((SUM('Raw Fs'!E41:E43)+SUM('Raw Fs'!D41:D43))/2),0) -> 19.479663 | D33: =IFERROR('Historicals FS'!D5/((SUM('Raw Fs'!F41:F43)+SUM('Raw Fs'!E41:E43))/2),0) -> 16.853739 | E33: =IFERROR('Historicals FS'!E5/((SUM('Raw Fs'!G41:G43)+SUM('Raw Fs'!F41:F43))/2),0) -> 14.393205 | F33: =IFERROR('Historicals FS'!F5/((SUM('Raw Fs'!H41:H43)+SUM('Raw Fs'!G41:G43))/2),0) -> 14.972776 | G33: =IFERROR('Historicals FS'!G5/((SUM('Raw Fs'!I41:I43)+SUM('Raw Fs'!H41:H43))/2),0) -> 19.457812 | H33: =IFERROR('Historicals FS'!H5/((SUM('Raw Fs'!J41:J43)+SUM('Raw Fs'!I41:I43))/2),0) -> 24.438662 | I33: =IFERROR('Historicals FS'!I5/((SUM('Raw Fs'!K41:K43)+SUM('Raw Fs'!J41:J43))/2),0) -> 26.179044 | J33: =IFERROR('Historicals FS'!J5/((SUM('Raw Fs'!L41:L43)+SUM('Raw Fs'!K41:K43))/2),0) -> 19.459164 | ... L33: =IFERROR('Historicals FS'!L5/((SUM('Raw Fs'!N41:N43)+SUM('Raw Fs'!M41:M43))/2),0) -> 18.250237 | N33: =AVERAGE(C33:L33) -> 19.070894 | O33: =MEDIAN(C33:L33) -> 18.854024
B34: Creditor Turnover Ratio | C34: =IFERROR(('Data Sheet'!B18/(SUM('Raw Fs'!D14:E14)/2)),0) -> 6.18511 | D34: =IFERROR(('Data Sheet'!C18/(SUM('Raw Fs'!E14:F14)/2)),0) -> 4.8181056 | E34: =IFERROR(('Data Sheet'!D18/(SUM('Raw Fs'!F14:G14)/2)),0) -> 5.0309792 | F34: =IFERROR(('Data Sheet'!E18/(SUM('Raw Fs'!G14:H14)/2)),0) -> 5.0556303 | G34: =IFERROR(('Data Sheet'!F18/(SUM('Raw Fs'!H14:I14)/2)),0) -> 5.2275028 | H34: =IFERROR(('Data Sheet'!G18/(SUM('Raw Fs'!I14:J14)/2)),0) -> 6.1975893 | I34: =IFERROR(('Data Sheet'!H18/(SUM('Raw Fs'!J14:K14)/2)),0) -> 6.4707713 | J34: =IFERROR(('Data Sheet'!I18/(SUM('Raw Fs'!K14:L14)/2)),0) -> 5.7837729 | ... L34: =IFERROR(('Data Sheet'!K18/(SUM('Raw Fs'!M14:N14)/2)),0) -> 6.7193146 | N34: =AVERAGE(C34:L34) -> 5.829864 | O34: =MEDIAN(C34:L34) -> 5.9844415
B35: Inventory Turnover Ratio | C35: =IFERROR(('Historicals FS'!C8/(SUM('Raw Fs'!D38:E38)/2)),0) -> 2.5554919 | D35: =IFERROR(('Historicals FS'!D8/(SUM('Raw Fs'!E38:F38)/2)),0) -> 2.8143617 | E35: =IFERROR(('Historicals FS'!E8/(SUM('Raw Fs'!F38:G38)/2)),0) -> 3.1541452 | F35: =IFERROR(('Historicals FS'!F8/(SUM('Raw Fs'!G38:H38)/2)),0) -> 2.9070315 | G35: =IFERROR(('Historicals FS'!G8/(SUM('Raw Fs'!H38:I38)/2)),0) -> 2.789117 | H35: =IFERROR(('Historicals FS'!H8/(SUM('Raw Fs'!I38:J38)/2)),0) -> 3.2033357 | I35: =IFERROR(('Historicals FS'!I8/(SUM('Raw Fs'!J38:K38)/2)),0) -> 3.3843278 | J35: =IFERROR(('Historicals FS'!J8/(SUM('Raw Fs'!K38:L38)/2)),0) -> 2.7515808 | ... L35: =IFERROR(('Historicals FS'!L8/(SUM('Raw Fs'!M38:N38)/2)),0) -> 2.5019451 | N35: =AVERAGE(C35:L35) -> 2.8845346 | O35: =MEDIAN(C35:L35) -> 2.8017394
B36: Fixed Asset Turnover Ratio | C36: =IFERROR(('Historicals FS'!C5/(SUM('Raw Fs'!D32:E32)/2)),0) -> 2.7592 | D36: =IFERROR(('Historicals FS'!D5/(SUM('Raw Fs'!E32:F32)/2)),0) -> 2.6806268 | E36: =IFERROR(('Historicals FS'!E5/(SUM('Raw Fs'!F32:G32)/2)),0) -> 2.6931629 | F36: =IFERROR(('Historicals FS'!F5/(SUM('Raw Fs'!G32:H32)/2)),0) -> 2.4040548 | G36: =IFERROR(('Historicals FS'!G5/(SUM('Raw Fs'!H32:I32)/2)),0) -> 2.188685 | H36: =IFERROR(('Historicals FS'!H5/(SUM('Raw Fs'!I32:J32)/2)),0) -> 2.5518963 | I36: =IFERROR(('Historicals FS'!I5/(SUM('Raw Fs'!J32:K32)/2)),0) -> 2.8321165 | J36: =IFERROR(('Historicals FS'!J5/(SUM('Raw Fs'!K32:L32)/2)),0) -> 2.5313735 | ... L36: =IFERROR(('Historicals FS'!L5/(SUM('Raw Fs'!M32:N32)/2)),0) -> 3.5528707 | N36: =AVERAGE(C36:L36) -> 2.7220479 | O36: =MEDIAN(C36:L36) -> 2.6868948
B37: Capital Turnover Ratio | C37: =IFERROR('Historicals FS'!C5/((SUM('Raw Fs'!E5:E6,'Raw Fs'!E8)+SUM('Raw Fs'!D5:D6,'Raw Fs'!D8))/2),0) -> 0.95958177 | D37: =IFERROR('Historicals FS'!D5/((SUM('Raw Fs'!F5:F6,'Raw Fs'!F8)+SUM('Raw Fs'!E5:E6,'Raw Fs'!E8))/2),0) -> 0.87817327 | E37: =IFERROR('Historicals FS'!E5/((SUM('Raw Fs'!G5:G6,'Raw Fs'!G8)+SUM('Raw Fs'!F5:F6,'Raw Fs'!F8))/2),0) -> 0.86574993 | F37: =IFERROR('Historicals FS'!F5/((SUM('Raw Fs'!H5:H6,'Raw Fs'!H8)+SUM('Raw Fs'!G5:G6,'Raw Fs'!G8))/2),0) -> 0.79383579 | G37: =IFERROR('Historicals FS'!G5/((SUM('Raw Fs'!I5:I6,'Raw Fs'!I8)+SUM('Raw Fs'!H5:H6,'Raw Fs'!H8))/2),0) -> 0.78415451 | H37: =IFERROR('Historicals FS'!H5/((SUM('Raw Fs'!J5:J6,'Raw Fs'!J8)+SUM('Raw Fs'!I5:I6,'Raw Fs'!I8))/2),0) -> 0.98759154 | I37: =IFERROR('Historicals FS'!I5/((SUM('Raw Fs'!K5:K6,'Raw Fs'!K8)+SUM('Raw Fs'!J5:J6,'Raw Fs'!J8))/2),0) -> 1.0776494 | J37: =IFERROR('Historicals FS'!J5/((SUM('Raw Fs'!L5:L6,'Raw Fs'!L8)+SUM('Raw Fs'!K5:K6,'Raw Fs'!K8))/2),0) -> 0.94568607 | ... L37: =IFERROR('Historicals FS'!L5/((SUM('Raw Fs'!N5:N6,'Raw Fs'!N8)+SUM('Raw Fs'!M5:M6,'Raw Fs'!M8))/2),0) -> 1.1061719 | N37: =AVERAGE(C37:L37) -> 0.94408505 | O37: =MEDIAN(C37:L37) -> 0.95263392
B38: 365
B39: Debtor Days | C39: =$B$38/C33 -> 18.737491 | D39: =$B$38/D33 -> 21.656915 | E39: =$B$38/E33 -> 25.359188 | F39: =$B$38/F33 -> 24.377578 | G39: =$B$38/G33 -> 18.758533 | H39: =$B$38/H33 -> 14.935351 | I39: =$B$38/I33 -> 13.94245 | J39: =$B$38/J33 -> 18.75723 | ... L39: =$B$38/L33 -> 19.99974 | N39: =AVERAGE(C39:L39) -> 19.771505 | O39: =MEDIAN(C39:L39) -> 19.379137
B40: Creditor Days | C40: =$B$38/C34 -> 59.012693 | D40: =$B$38/D34 -> 75.755915 | E40: =$B$38/E34 -> 72.550489 | F40: =$B$38/F34 -> 72.196735 | G40: =$B$38/G34 -> 69.823013 | H40: =$B$38/H34 -> 58.893867 | I40: =$B$38/I34 -> 56.407495 | J40: =$B$38/J34 -> 63.107596 | ... L40: =$B$38/L34 -> 54.321016 | N40: =AVERAGE(C40:L40) -> 63.566754 | O40: =MEDIAN(C40:L40) -> 61.060144
B41: Inventory Days | C41: =$B$38/C35 -> 142.82964 | D41: =$B$38/D35 -> 129.69193 | E41: =$B$38/E35 -> 115.72073 | F41: =$B$38/F35 -> 125.55764 | G41: =$B$38/G35 -> 130.86579 | H41: =$B$38/H35 -> 113.94372 | I41: =$B$38/I35 -> 107.85007 | J41: =$B$38/J35 -> 132.65102 | ... L41: =$B$38/L35 -> 145.8865 | N41: =AVERAGE(C41:L41) -> 127.61029 | O41: =MEDIAN(C41:L41) -> 130.27886
